<?xml version="1.0" encoding="UTF-8"?>
<robot name="alfiebot">

  <material name="aluminum_black">
    <color rgba="0.05 0.05 0.05 1"/>
  </material>

  <material name="body_black">
    <color rgba="0.1 0.1 0.1 1"/>
  </material>

  <material name="plastic_black">
    <color rgba="0.05 0.05 0.05 1"/>
  </material>

  <material name="glass_black">
    <color rgba="0.05 0.05 0.05 1"/>
  </material>

  <material name="brass">
    <color rgba="0.8 0.5 0.2 1"/>
  </material>

  <material name="plastic_white">
    <color rgba="0.9 0.9 0.9 1"/>
  </material>

  <material name="aluminum">
    <color rgba="0.66 0.67 0.71 1"/>
  </material>

  <material name="body_black">
    <color rgba="0.25 0.25 0.25 1"/>
  </material>

  <material name="rubber_black">
    <color rgba="0.05 0.05 0.05 1"/>
  </material>

  <material name="glass_yellow">
    <color rgba="0.8 0.8 0.0 1"/>
  </material>

  <material name="rubber_orange">
    <color rgba="0.8 0.4 0.0 1"/>
  </material>

  <material name="plastic_orange">
    <color rgba="0.8 0.4 0.0 1"/>
  </material>

  <material name="plastic_grey">
    <color rgba="0.2 0.2 0.2 1"/>
  </material>

  <joint name="back_joint" type="prismatic">
    <origin xyz="-0.001102 0.0016674 0.3291568" rpy="0. 0. 3.1415927"/>
    <parent link="base_link"/>
    <child link="back_link"/>
    <axis xyz="0. 0. 1."/>
    <limit lower="0." upper="0.39" effort="10000000." velocity="0."/>
  </joint>
  <joint name="head_pitch_joint" type="revolute">
    <origin xyz="-0.01875 -0. 0.053 " rpy="1.5707964 0.0 1.5707964"/>
    <parent link="neck2_link"/>
    <child link="neck3_link"/>
    <axis xyz="0. 0. -1."/>
    <limit lower="-1.0471976" upper="1.0471976" effort="10000000." velocity="0."/>
  </joint>
  <joint name="head_roll_joint" type="continuous">
    <origin xyz="0.0506271 0.0001069 0.0194332" rpy="-1.5707964 0. 1.5707964"/>
    <parent link="neck3_link"/>
    <child link="head_link"/>
    <axis xyz="0. 0. 1."/>
  </joint>
  <joint name="head_yaw_joint" type="revolute">
    <origin xyz="-0.0011403 0.0054173 0.8706568" rpy="0.0 0.0 0.0"/>
    <parent link="base_link"/>
    <child link="neck2_link"/>
    <axis xyz="0. 0. 1."/>
    <limit lower="-3.1415927" upper="3.1415927" effort="10000000." velocity="0."/>
  </joint>
  <joint name="left_elbow_pitch_joint" type="revolute">
    <origin xyz="0.2368151 -0.0300024 0.0193 " rpy="0. 0. 1.5707964"/>
    <parent link="left_arm_upper_link"/>
    <child link="left_arm_lower_link"/>
    <axis xyz="0. 0. 1."/>
    <limit lower="-1.5707963" upper="1.5707963" effort="10000000." velocity="0."/>
  </joint>
  <joint name="left_gripper_active_joint" type="revolute">
    <origin xyz="-0.0052 -0.015625 0.021 " rpy="-1.5707964 0. -1.5707964"/>
    <parent link="left_hand_link"/>
    <child link="left_gripper_active_link"/>
    <axis xyz="0. 0. 1."/>
    <limit lower="-0.0872665" upper="0.7853982" effort="10000000." velocity="0."/>
  </joint>
  <joint name="left_gripper_passive_joint" type="revolute">
    <origin xyz="-0.0052 0.015625 0.021 " rpy="-1.5707964 0. -1.5707964"/>
    <parent link="left_hand_link"/>
    <child link="left_gripper_passive_link"/>
    <axis xyz="0. 0. 1."/>
    <limit lower="-0.7853982" upper="0.0872665" effort="10000000." velocity="0."/>
  </joint>
  <joint name="left_shoulder_pitch_joint" type="revolute">
    <origin xyz="0.0379175 0.0000265 -0.0508856" rpy="0. 1.5707961 -3.1415927"/>
    <parent link="left_shoulder_link"/>
    <child link="left_arm_upper_link"/>
    <axis xyz="0. 0. 1."/>
    <limit lower="-1.4835299" upper="1.4835299" effort="10000000." velocity="0."/>
  </joint>
  <joint name="left_shoulder_yaw_joint" type="revolute">
    <origin xyz="-0.098 -0.007 0.04 " rpy="0. 0. 0."/>
    <parent link="back_link"/>
    <child link="left_shoulder_link"/>
    <axis xyz="0. 0. 1."/>
    <limit lower="-0.7853982" upper="0.7853982" effort="10000000." velocity="0."/>
  </joint>
  <joint name="left_wrist_pitch_joint" type="revolute">
    <origin xyz="-0.2158563 -0.005356 0.0004384" rpy="0. -0.0000002 -1.5707964"/>
    <parent link="left_arm_lower_link"/>
    <child link="left_wrist_link"/>
    <axis xyz="0. 0. 1."/>
    <limit lower="-0.7853982" upper="1.5707963" effort="10000000." velocity="0."/>
  </joint>
  <joint name="left_wrist_roll_joint" type="revolute">
    <origin xyz="-0. -0.05525 0.019 " rpy="-1.5707964 -0.0000002 -3.1415927"/>
    <parent link="left_wrist_link"/>
    <child link="left_hand_link"/>
    <axis xyz="0. 0. 1."/>
    <limit lower="-1.5707963" upper="1.5707963" effort="10000000." velocity="0."/>
  </joint>
  <joint name="mecanum_fl_joint" type="continuous">
    <origin xyz="0.0587987 -0.0400623 -0.0190932" rpy="1.5707964 0. 1.5707964"/>
    <parent link="base_link"/>
    <child link="mecanum_fl_link"/>
    <axis xyz="0. 0. 1."/>
  </joint>
  <joint name="mecanum_fr_joint" type="continuous">
    <origin xyz="-0.0614028 -0.0400623 -0.0190932" rpy="1.5707964 0. 1.5707964"/>
    <parent link="base_link"/>
    <child link="mecanum_fr_link"/>
    <axis xyz="0. 0. 1."/>
  </joint>
  <joint name="mecanum_rl_joint" type="continuous">
    <origin xyz="0.0587987 0.1309377 -0.0190932" rpy="1.5707964 0. 1.5707964"/>
    <parent link="base_link"/>
    <child link="mecanum_rl_link"/>
    <axis xyz="0. 0. 1."/>
  </joint>
  <joint name="mecanum_rr_joint" type="continuous">
    <origin xyz="-0.0614028 0.1309377 -0.0190932" rpy="1.5707964 0. 1.5707964"/>
    <parent link="base_link"/>
    <child link="mecanum_rr_link"/>
    <axis xyz="0. 0. 1."/>
  </joint>
  <joint name="right_elbow_pitch_joint" type="revolute">
    <origin xyz="0.2368151 -0.0300024 0.0193 " rpy="0.0000001 -0.0000001 1.5707963"/>
    <parent link="right_arm_upper_link"/>
    <child link="right_arm_lower_link"/>
    <axis xyz="0. 0. 1."/>
    <limit lower="-1.5707963" upper="1.5707963" effort="10000000." velocity="0."/>
  </joint>
  <joint name="right_gripper_active_joint" type="revolute">
    <origin xyz="0.0052 0.015625 0.021 " rpy="-1.5707964 0. 1.5707964"/>
    <parent link="right_hand_link"/>
    <child link="right_gripper_active_link"/>
    <axis xyz="0. 0. 1."/>
    <limit lower="-0.0872665" upper="0.7853982" effort="10000000." velocity="0."/>
  </joint>
  <joint name="right_gripper_passive_joint" type="revolute">
    <origin xyz="0.0052 -0.015625 0.021 " rpy="-1.5707964 0. 1.5707964"/>
    <parent link="right_hand_link"/>
    <child link="right_gripper_passive_link"/>
    <axis xyz="0. 0. 1."/>
    <limit lower="-0.7853982" upper="0.0872665" effort="10000000." velocity="0."/>
  </joint>
  <joint name="right_shoulder_pitch_joint" type="revolute">
    <origin xyz="0.0379175 0.0000265 -0.0508856" rpy="0. 1.5707961 3.1415927"/>
    <parent link="right_shoulder_link"/>
    <child link="right_arm_upper_link"/>
    <axis xyz="0. 0. 1."/>
    <limit lower="-1.4835299" upper="1.4835299" effort="10000000." velocity="0."/>
  </joint>
  <joint name="right_shoulder_yaw_joint" type="revolute">
    <origin xyz="0.098 -0.007 0.04 " rpy="0. 0. 0."/>
    <parent link="back_link"/>
    <child link="right_shoulder_link"/>
    <axis xyz="0. 0. 1."/>
    <limit lower="-0.7853982" upper="0.7853982" effort="10000000." velocity="0."/>
  </joint>
  <joint name="right_wrist_pitch_joint" type="revolute">
    <origin xyz="-0.2158563 -0.005356 0.0004384" rpy="-0.0000001 -0.0000001 -1.5707963"/>
    <parent link="right_arm_lower_link"/>
    <child link="right_wrist_link"/>
    <axis xyz="0. 0. 1."/>
    <limit lower="-0.7853982" upper="1.5707963" effort="10000000." velocity="0."/>
  </joint>
  <joint name="right_wrist_roll_joint" type="revolute">
    <origin xyz="-0. -0.05525 0.0185 " rpy="1.5707964 0.0000002 -0. "/>
    <parent link="right_wrist_link"/>
    <child link="right_hand_link"/>
    <axis xyz="0. 0. 1."/>
    <limit lower="-1.5707963" upper="1.5707963" effort="10000000." velocity="0."/>
  </joint>


  <link name="back_link">
    <inertial>
      <origin xyz="-0.051 -0.0073 0.053 " rpy="0. 0. 0."/>
      <mass value="0.0114743"/>
      <inertia ixx="0.0000005" ixy="-0." ixz="0." iyy="0.0000005" iyz="-0." izz="0.0000008"/>
    </inertial>
    <visual>
      <origin xyz="-0.098 -0.007 0.05725" rpy="0. 0. 1.5707964"/>
      <geometry>
        <mesh filename="package://alfie_urdf/meshes/st3215.obj" scale="1. 1. 1."/>
      </geometry>
      <material name="plastic_black"/>
    </visual>
    <visual>
      <origin xyz="-0. -0.0064 0.04 " rpy="3.1415927 0. 0. "/>
      <geometry>
        <mesh filename="package://alfie_urdf/meshes/v_bearing.obj" scale="1. 1. 1."/>
      </geometry>
      <material name="plastic_black"/>
    </visual>
    <visual>
      <origin xyz="-0. -0.007 0.1 " rpy="0. 0. 0."/>
      <geometry>
        <mesh filename="package://alfie_urdf/meshes/pillow_block_adapter.obj" scale="1. 1. 1."/>
      </geometry>
      <material name="body_black"/>
    </visual>
    <visual>
      <origin xyz="-0. -0.007 0.1 " rpy="0. 0. 0."/>
      <geometry>
        <mesh filename="package://alfie_urdf/meshes/left_shoulder.obj" scale="1. 1. 1."/>
      </geometry>
      <material name="body_black"/>
    </visual>
    <visual>
      <origin xyz="-0. -0.007 0.1 " rpy="0. 0. 0."/>
      <geometry>
        <mesh filename="package://alfie_urdf/meshes/back_frame.obj" scale="1. 1. 1."/>
      </geometry>
      <material name="body_black"/>
    </visual>
    <visual>
      <origin xyz="0.0009153 -0.0064 0.0736835" rpy="3.1415927 0. 0. "/>
      <geometry>
        <mesh filename="package://alfie_urdf/meshes/v_bearing.obj" scale="1. 1. 1."/>
      </geometry>
      <material name="plastic_black"/>
    </visual>
    <visual>
      <origin xyz="-0.1029153 -0.0064 0.0736835" rpy="3.1415927 0. 0. "/>
      <geometry>
        <mesh filename="package://alfie_urdf/meshes/v_bearing.obj" scale="1. 1. 1."/>
      </geometry>
      <material name="plastic_black"/>
    </visual>
    <visual>
      <origin xyz="0.098 -0.007 0.05725" rpy="0. 0. 1.5707964"/>
      <geometry>
        <mesh filename="package://alfie_urdf/meshes/st3215.obj" scale="1. 1. 1."/>
      </geometry>
      <material name="plastic_black"/>
    </visual>
    <visual>
      <origin xyz="-0. -0.007 0.1 " rpy="0. 0. 0."/>
      <geometry>
        <mesh filename="package://alfie_urdf/meshes/right_shoulder.obj" scale="1. 1. 1."/>
      </geometry>
      <material name="body_black"/>
    </visual>
    <visual>
      <origin xyz="-0.102 -0.0064 0.04 " rpy="3.1415927 0. 0. "/>
      <geometry>
        <mesh filename="package://alfie_urdf/meshes/v_bearing.obj" scale="1. 1. 1."/>
      </geometry>
      <material name="plastic_black"/>
    </visual>
  </link>

  <link name="base_link">
    <inertial>
      <origin xyz="-0.0846182 0.0894767 0.0393554" rpy="0. 0. 0."/>
      <mass value="0.17555"/>
      <inertia ixx="0.000074" ixy="0." ixz="0." iyy="0.0001197" iyz="0.0000151" izz="0.0000903"/>
    </inertial>
    <visual>
      <origin xyz="-0.001302 0.0336644 0.2746568" rpy="0. 0. 3.1415927"/>
      <geometry>
        <mesh filename="package://alfie_urdf/meshes/optical_endstop_block.obj" scale="1. 1. 1."/>
      </geometry>
      <material name="body_black"/>
    </visual>
    <visual>
      <origin xyz="-0.001302 0.0331644 0.0276568" rpy="0. 0. 1.5707964"/>
      <geometry>
        <mesh filename="package://alfie_urdf/meshes/buck_converter.obj" scale="1. 1. 1."/>
      </geometry>
      <material name="aluminum"/>
    </visual>
    <visual>
      <origin xyz="-0.0011033 0.0196107 0.8266568" rpy="0. 0. -0.0025961"/>
      <geometry>
        <mesh filename="package://alfie_urdf/meshes/neck_base.obj" scale="1. 1. 1."/>
      </geometry>
      <material name="body_black"/>
    </visual>
    <visual>
      <origin xyz="-0.001302 0.0196644 0.0449068" rpy="0. 0. 3.1415927"/>
      <geometry>
        <mesh filename="package://alfie_urdf/meshes/battery_adapter_plate.obj" scale="1. 1. 1."/>
      </geometry>
      <material name="body_black"/>
    </visual>
    <visual>
      <origin xyz="-0.001135 0.0916674 0.7974541" rpy="3.1415927 0. 0. "/>
      <geometry>
        <mesh filename="package://alfie_urdf/meshes/back_servo_cover.obj" scale="1. 1. 1."/>
      </geometry>
      <material name="body_black"/>
    </visual>
    <visual>
      <origin xyz="0.0542753 0.0684031 0.0314471" rpy="0. 0. 0."/>
      <geometry>
        <mesh filename="package://alfie_urdf/meshes/wifi_antenna.obj" scale="1. 1. 1."/>
      </geometry>
      <material name="plastic_black"/>
    </visual>
    <visual>
      <origin xyz="-0.001102 0.0196644 0.0271568" rpy="0. 0. 3.1415927"/>
      <geometry>
        <mesh filename="package://alfie_urdf/meshes/flsun_arm.obj" scale="1. 1. 1."/>
      </geometry>
      <material name="aluminum_black"/>
    </visual>
    <visual>
      <origin xyz="-0.001135 0.0296674 0.7974541" rpy="1.5707964 0. 0. "/>
      <geometry>
        <mesh filename="package://alfie_urdf/meshes/jgb37_520.obj" scale="1. 1. 1."/>
      </geometry>
      <material name="aluminum"/>
    </visual>
    <visual>
      <origin xyz="0.0542753 0.0684031 0.0314471" rpy="0. 0. 0."/>
      <geometry>
        <mesh filename="package://alfie_urdf/meshes/wifi_nut.obj" scale="1. 1. 1."/>
      </geometry>
      <material name="brass"/>
    </visual>
    <visual>
      <origin xyz="-0.001302 0.0463674 0.0241568" rpy="0. 0. 0."/>
      <geometry>
        <mesh filename="package://alfie_urdf/meshes/base_plate.obj" scale="1. 1. 1."/>
      </geometry>
      <material name="body_black"/>
    </visual>
    <visual>
      <origin xyz="-0.0011403 0.0054173 0.8514068" rpy="-3.1415927 0. -1.5733924"/>
      <geometry>
        <mesh filename="package://alfie_urdf/meshes/st3215.obj" scale="1. 1. 1."/>
      </geometry>
      <material name="plastic_black"/>
    </visual>
    <visual>
      <origin xyz="-0.0846183 0.0741196 0.0619034" rpy="-1.1724066 0. 0. "/>
      <geometry>
        <mesh filename="package://alfie_urdf/meshes/speaker_accent.obj" scale="1. 1. 1."/>
      </geometry>
      <material name="plastic_orange"/>
    </visual>
    <visual>
      <origin xyz="0.0542854 0.0531264 0.0314244" rpy="0. 0. 0."/>
      <geometry>
        <mesh filename="package://alfie_urdf/meshes/wifi_antenna.obj" scale="1. 1. 1."/>
      </geometry>
      <material name="plastic_black"/>
    </visual>
    <visual>
      <origin xyz="-0.001302 0.0454377 0.0241568" rpy="0. 0. 0."/>
      <geometry>
        <mesh filename="package://alfie_urdf/meshes/ugv_base.obj" scale="1. 1. 1."/>
      </geometry>
      <material name="aluminum_black"/>
    </visual>
    <visual>
      <origin xyz="-0.0846183 0.0741196 0.0619034" rpy="-1.1724066 0. 0. "/>
      <geometry>
        <mesh filename="package://alfie_urdf/meshes/speaker.obj" scale="1. 1. 1."/>
      </geometry>
      <material name="plastic_black"/>
    </visual>
    <visual>
      <origin xyz="-0.001102 0.0196644 0.0271568" rpy="0. 0. 3.1415927"/>
      <geometry>
        <mesh filename="package://alfie_urdf/meshes/flsun_rail.obj" scale="1. 1. 1."/>
      </geometry>
      <material name="aluminum"/>
    </visual>
    <visual>
      <origin xyz="-0.001302 0.0832644 0.0241568" rpy="0. 0. 1.5707964"/>
      <geometry>
        <mesh filename="package://alfie_urdf/meshes/buckdown_spacer.obj" scale="1. 1. 1."/>
      </geometry>
      <material name="body_black"/>
    </visual>
    <visual>
      <origin xyz="0.0542854 0.0531264 0.0314244" rpy="0. 0. 0."/>
      <geometry>
        <mesh filename="package://alfie_urdf/meshes/wifi_nut.obj" scale="1. 1. 1."/>
      </geometry>
      <material name="brass"/>
    </visual>
    <visual>
      <origin xyz="-0.001135 0.0196674 0.7974541" rpy="3.1415927 0. 0. "/>
      <geometry>
        <mesh filename="package://alfie_urdf/meshes/back_servo_frame.obj" scale="1. 1. 1."/>
      </geometry>
      <material name="body_black"/>
    </visual>
    <visual>
      <origin xyz="-0.0846183 0.0741196 0.0619034" rpy="-1.1724066 0. 0. "/>
      <geometry>
        <mesh filename="package://alfie_urdf/meshes/speaker.obj" scale="1. 1. 1."/>
      </geometry>
      <material name="plastic_grey"/>
    </visual>
    <visual>
      <origin xyz="-0.001102 0.0196644 0.0271568" rpy="0. 0. 3.1415927"/>
      <geometry>
        <mesh filename="package://alfie_urdf/meshes/flsun_rail.obj" scale="1. 1. 1."/>
      </geometry>
      <material name="aluminum"/>
    </visual>
    <visual>
      <origin xyz="-0.001302 0.0832644 0.0241568" rpy="0. 0. 1.5707964"/>
      <geometry>
        <mesh filename="package://alfie_urdf/meshes/buckdown_spacer.obj" scale="1. 1. 1."/>
      </geometry>
      <material name="body_black"/>
    </visual>
    <visual>
      <origin xyz="0.0542854 0.0531264 0.0314244" rpy="0. 0. 0."/>
      <geometry>
        <mesh filename="package://alfie_urdf/meshes/wifi_nut.obj" scale="1. 1. 1."/>
      </geometry>
      <material name="brass"/>
    </visual>
    <visual>
      <origin xyz="-0.001135 0.0196674 0.7974541" rpy="3.1415927 0. 0. "/>
      <geometry>
        <mesh filename="package://alfie_urdf/meshes/back_servo_frame.obj" scale="1. 1. 1."/>
      </geometry>
      <material name="body_black"/>
    </visual>
    <visual>
      <origin xyz="-0.0010395 0.0334644 0.074102 " rpy="0. -1.5707964 0. "/>
      <geometry>
        <mesh filename="package://alfie_urdf/meshes/6010_battery.obj" scale="1. 1. 1."/>
      </geometry>
      <material name="plastic_black"/>
    </visual>
    <visual>
      <origin xyz="-0.0846183 0.0741196 0.0619034" rpy="-1.1724066 0. 0. "/>
      <geometry>
        <mesh filename="package://alfie_urdf/meshes/speaker_cover.obj" scale="1. 1. 1."/>
      </geometry>
      <material name="plastic_black"/>
    </visual>
    <visual>
      <origin xyz="-0.0846183 0.0741196 0.0619034" rpy="-1.1724066 0. 0. "/>
      <geometry>
        <mesh filename="package://alfie_urdf/meshes/speaker_base.obj" scale="1. 1. 1."/>
      </geometry>
      <material name="plastic_black"/>
    </visual>
  </link>

  <link name="head_link">
    <inertial>
      <origin xyz="-0. -0. -0.0354969" rpy="0. 0. 0."/>
      <mass value="0.001042"/>
      <inertia ixx="0." ixy="-0." ixz="-0." iyy="0." iyz="-0." izz="0."/>
    </inertial>
    <visual>
      <origin xyz="-0. -0. -0.01725" rpy="3.1415927 -0. 1.5707964"/>
      <geometry>
        <mesh filename="package://alfie_urdf/meshes/st3215.obj" scale="1. 1. 1."/>
      </geometry>
      <material name="plastic_black"/>
    </visual>
    <visual>
      <origin xyz="0.0071363 0.0002454 0.0970189" rpy="-1.5707964 0. -1.5707964"/>
      <geometry>
        <mesh filename="package://alfie_urdf/meshes/oakd_lite.obj" scale="1. 1. 1."/>
      </geometry>
      <material name="plastic_black"/>
    </visual>
    <visual>
      <origin xyz="-0. -0. -0.01725" rpy="-3.1415927 0. -1.5707964"/>
      <geometry>
        <mesh filename="package://alfie_urdf/meshes/active_horn.obj" scale="1. 1. 1."/>
      </geometry>
      <material name="plastic_white"/>
    </visual>
    <visual>
      <origin xyz="-0.0967828 0.0002681 0.0396251" rpy="-1.5707964 0. -1.5707964"/>
      <geometry>
        <mesh filename="package://alfie_urdf/meshes/respeaker.obj" scale="1. 1. 1."/>
      </geometry>
      <material name="plastic_black"/>
    </visual>
    <visual>
      <origin xyz="-0.0944828 0.1128894 0.036915 " rpy="-1.5707964 0. -1.5707964"/>
      <geometry>
        <mesh filename="package://alfie_urdf/meshes/eye_glass.obj" scale="1. 1. 1."/>
      </geometry>
      <material name="glass_yellow"/>
    </visual>
    <visual>
      <origin xyz="-0.0944828 0.0008894 0.036915 " rpy="-1.5707964 0. -1.5707964"/>
      <geometry>
        <mesh filename="package://alfie_urdf/meshes/eye_glass.obj" scale="1. 1. 1."/>
      </geometry>
      <material name="glass_yellow"/>
    </visual>
    <visual>
      <origin xyz="0.00775 0.0002454 0.0365189" rpy="-1.5707964 0. -1.5707964"/>
      <geometry>
        <mesh filename="package://alfie_urdf/meshes/head_frame.obj" scale="1. 1. 1."/>
      </geometry>
      <material name="aluminum_black"/>
    </visual>
    <visual>
      <origin xyz="-0.0944828 0.1128894 0.036915 " rpy="-1.5707964 0. -1.5707964"/>
      <geometry>
        <mesh filename="package://alfie_urdf/meshes/eye_frame.obj" scale="1. 1. 1."/>
      </geometry>
      <material name="aluminum_black"/>
    </visual>
    <visual>
      <origin xyz="-0. -0. -0.0357" rpy="-1.5707964 0. -1.5707964"/>
      <geometry>
        <mesh filename="package://alfie_urdf/meshes/neck4_frame.obj" scale="1. 1. 1."/>
      </geometry>
      <material name="aluminum_black"/>
    </visual>
    <visual>
      <origin xyz="-0.0944828 0.0008894 0.036915 " rpy="-1.5707964 0. -1.5707964"/>
      <geometry>
        <mesh filename="package://alfie_urdf/meshes/eye_frame.obj" scale="1. 1. 1."/>
      </geometry>
      <material name="aluminum_black"/>
    </visual>
    <visual>
      <origin xyz="-0. -0. -0.01725" rpy="-3.1415927 0. -1.5707964"/>
      <geometry>
        <mesh filename="package://alfie_urdf/meshes/passive_horn.obj" scale="1. 1. 1."/>
      </geometry>
      <material name="plastic_white"/>
    </visual>
  </link>

  <link name="left_arm_lower_link">
    <inertial>
      <origin xyz="-0.0133899 0. 0.0192034" rpy="0. 0. 0."/>
      <mass value="0.0951702"/>
      <inertia ixx="0.0000129" ixy="0." ixz="-0." iyy="0.0000204" iyz="-0." izz="0.0000236"/>
    </inertial>
    <visual>
      <origin xyz="0.0672499 0.5326688 -0.0786977" rpy="1.5707964 1.5707964 0. "/>
      <geometry>
        <mesh filename="package://alfie_urdf/meshes/tube.obj" scale="1. 1. 1."/>
      </geometry>
      <material name="plastic_black"/>
    </visual>
    <visual>
      <origin xyz="-0.2158563 -0.0012424 0.017225 " rpy="0. 0. 1.5707964"/>
      <geometry>
        <mesh filename="package://alfie_urdf/meshes/passive_horn.obj" scale="1. 1. 1."/>
      </geometry>
      <material name="plastic_white"/>
    </visual>
    <visual>
      <origin xyz="0.0672499 -0.539283 0.1163364" rpy="-1.5707964 -1.5707964 0. "/>
      <geometry>
        <mesh filename="package://alfie_urdf/meshes/wrist_frame.obj" scale="1. 1. 1."/>
      </geometry>
      <material name="aluminum_black"/>
    </visual>
    <visual>
      <origin xyz="0.0672499 -0.5392672 0.1163611" rpy="-1.5707964 -1.5707964 0. "/>
      <geometry>
        <mesh filename="package://alfie_urdf/meshes/bracket_lower.obj" scale="1. 1. 1."/>
      </geometry>
      <material name="plastic_grey"/>
    </visual>
    <visual>
      <origin xyz="0.0672499 -0.5392672 0.1163611" rpy="-1.5707964 -1.5707964 0. "/>
      <geometry>
        <mesh filename="package://alfie_urdf/meshes/elbow_frame.obj" scale="1. 1. 1."/>
      </geometry>
      <material name="aluminum_black"/>
    </visual>
    <visual>
      <origin xyz="0. 0. 0.01725" rpy="0. 0. -1.5707964"/>
      <geometry>
        <mesh filename="package://alfie_urdf/meshes/passive_horn.obj" scale="1. 1. 1."/>
      </geometry>
      <material name="plastic_white"/>
    </visual>
    <visual>
      <origin xyz="0.0672499 -0.5392672 0.1163611" rpy="-1.5707964 -1.5707964 0. "/>
      <geometry>
        <mesh filename="package://alfie_urdf/meshes/bracket_upper.obj" scale="1. 1. 1."/>
      </geometry>
      <material name="plastic_grey"/>
    </visual>
    <visual>
      <origin xyz="0.0672499 -0.539283 0.1163364" rpy="-1.5707964 -1.5707964 0. "/>
      <geometry>
        <mesh filename="package://alfie_urdf/meshes/bracket_lower.obj" scale="1. 1. 1."/>
      </geometry>
      <material name="plastic_grey"/>
    </visual>
    <visual>
      <origin xyz="-0.2158563 -0.005356 0.0204384" rpy="3.1415927 0. 3.1415927"/>
      <geometry>
        <mesh filename="package://alfie_urdf/meshes/st3215.obj" scale="1. 1. 1."/>
      </geometry>
      <material name="plastic_black"/>
    </visual>
    <visual>
      <origin xyz="-0.2158563 -0.0012424 0.017225 " rpy="0. 0. 1.5707964"/>
      <geometry>
        <mesh filename="package://alfie_urdf/meshes/active_horn.obj" scale="1. 1. 1."/>
      </geometry>
      <material name="plastic_white"/>
    </visual>
    <visual>
      <origin xyz="0. 0. 0.01725" rpy="0. 0. -1.5707964"/>
      <geometry>
        <mesh filename="package://alfie_urdf/meshes/active_horn.obj" scale="1. 1. 1."/>
      </geometry>
      <material name="plastic_white"/>
    </visual>
    <visual>
      <origin xyz="0.0672499 -0.539283 0.1163364" rpy="-1.5707964 -1.5707964 0. "/>
      <geometry>
        <mesh filename="package://alfie_urdf/meshes/bracket_upper.obj" scale="1. 1. 1."/>
      </geometry>
      <material name="plastic_grey"/>
    </visual>
    <visual>
      <origin xyz="0. 0. 0.01725" rpy="0. 0. 0."/>
      <geometry>
        <mesh filename="package://alfie_urdf/meshes/st3215.obj" scale="1. 1. 1."/>
      </geometry>
      <material name="plastic_black"/>
    </visual>
  </link>

  <link name="left_arm_upper_link">
    <inertial>
      <origin xyz="0.1212153 -0.0000903 0.03801 " rpy="0. 0. 0."/>
      <mass value="0.1877193"/>
      <inertia ixx="0.0009182" ixy="-0." ixz="-0." iyy="0.0008838" iyz="-0." izz="0.0000578"/>
    </inertial>
    <visual>
      <origin xyz="0.7760407 0.0370184 0.1359393" rpy="-0. -1.5707961 0. "/>
      <geometry>
        <mesh filename="package://alfie_urdf/meshes/upper_frame.obj" scale="1. 1. 1."/>
      </geometry>
      <material name="aluminum_black"/>
    </visual>
  </link>

  <link name="left_gripper_active_link">
    <inertial>
      <origin xyz="-0.0001356 -0.0333035 0.005 " rpy="0. 0. 0."/>
      <mass value="0.0211625"/>
      <inertia ixx="0.0000013" ixy="0." ixz="-0." iyy="0.0000198" iyz="0." izz="0.0000203"/>
    </inertial>
    <visual>
      <origin xyz="-0.03125 0. 0.015 " rpy="3.1415927 0. 3.1415927"/>
      <geometry>
        <mesh filename="package://alfie_urdf/meshes/gripper_liner.obj" scale="1. 1. 1."/>
      </geometry>
      <material name="rubber_orange"/>
    </visual>
    <visual>
      <origin xyz="-0.03125 0. 0.015 " rpy="3.1415927 0. 3.1415927"/>
      <geometry>
        <mesh filename="package://alfie_urdf/meshes/gripper.obj" scale="1. 1. 1."/>
      </geometry>
      <material name="body_black"/>
    </visual>
    <collision>
      <origin xyz="-0.0313332 -0.0001633 -0.0049882" rpy="0. 0. 0."/>
      <geometry>
        <mesh filename="package://alfie_urdf/meshes/gripper_active_collision.obj" scale="1. 1. 1."/>
      </geometry>
    </collision>
  </link>

  <link name="left_gripper_passive_link">
    <inertial>
      <origin xyz="0.0001356 -0.0333035 0.005 " rpy="0. 0. 0."/>
      <mass value="0.0211625"/>
      <inertia ixx="0.0000013" ixy="0." ixz="0." iyy="0.0000198" iyz="0." izz="0.0000203"/>
    </inertial>
    <visual>
      <origin xyz="0.03125 -0. -0.005 " rpy="0. 0. 0."/>
      <geometry>
        <mesh filename="package://alfie_urdf/meshes/gripper_liner.obj" scale="1. 1. 1."/>
      </geometry>
      <material name="rubber_orange"/>
    </visual>
    <visual>
      <origin xyz="0.03125 -0. -0.005 " rpy="0. 0. 0."/>
      <geometry>
        <mesh filename="package://alfie_urdf/meshes/gripper.obj" scale="1. 1. 1."/>
      </geometry>
      <material name="body_black"/>
    </visual>
    <collision>
      <origin xyz="0.031 -0.0003 -0.0044" rpy="0. 0. 0."/>
      <geometry>
        <mesh filename="package://alfie_urdf/meshes/gripper_passive_collision.obj" scale="1. 1. 1."/>
      </geometry>
      <material name="plastic_black"/>
    </collision>
  </link>

  <link name="left_hand_link">
    <inertial>
      <origin xyz="0.0009873 0.0011172 0.0124377" rpy="0. 0. 0."/>
      <mass value="0.0225604"/>
      <inertia ixx="0.0000078" ixy="0." ixz="0." iyy="0.0000033" iyz="-0." izz="0.0000065"/>
    </inertial>
    <visual>
      <origin xyz="-0.02245 -0.015625 0.021 " rpy="1.5707964 -0.0148905 -1.5707964"/>
      <geometry>
        <mesh filename="package://alfie_urdf/meshes/st3215.obj" scale="1. 1. 1."/>
      </geometry>
      <material name="plastic_black"/>
    </visual>
    <visual>
      <origin xyz="-0.01 -0.015625 0.021 " rpy="-1.5707964 0. -1.5707964"/>
      <geometry>
        <mesh filename="package://alfie_urdf/meshes/hand_frame.obj" scale="1. 1. 1."/>
      </geometry>
      <material name="aluminum_black"/>
    </visual>
  </link>

  <link name="left_shoulder_link">
    <inertial>
      <origin xyz="-0.035563 -0.0000007 -0.0509092" rpy="0. 0. 0."/>
      <mass value="0.0014148"/>
      <inertia ixx="0.0000001" ixy="0." ixz="-0." iyy="0." iyz="-0." izz="0."/>
    </inertial>
    <visual>
      <origin xyz="-0.0001294 -0.0002184 -0.0003 " rpy="0. 0. 3.1415927"/>
      <geometry>
        <mesh filename="package://alfie_urdf/meshes/shoulder_frame.obj" scale="1. 1. 1."/>
      </geometry>
      <material name="aluminum_black"/>
    </visual>
    <visual>
      <origin xyz="0.0206675 0.0000265 -0.0508856" rpy="3.1415927 1.5707964 0. "/>
      <geometry>
        <mesh filename="package://alfie_urdf/meshes/active_horn.obj" scale="1. 1. 1."/>
      </geometry>
      <material name="plastic_white"/>
    </visual>
    <visual>
      <origin xyz="-0.0206912 -0.0000007 -0.0509092" rpy="0. 1.5707964 0. "/>
      <geometry>
        <mesh filename="package://alfie_urdf/meshes/passive_horn.obj" scale="1. 1. 1."/>
      </geometry>
      <material name="plastic_white"/>
    </visual>
    <visual>
      <origin xyz="0.0206675 0.0000265 -0.0508856" rpy="3.1415927 1.5707964 0. "/>
      <geometry>
        <mesh filename="package://alfie_urdf/meshes/passive_horn.obj" scale="1. 1. 1."/>
      </geometry>
      <material name="plastic_white"/>
    </visual>
    <visual>
      <origin xyz="-0.0001294 -0.0002184 -0.0003 " rpy="0. 0. 3.1415927"/>
      <geometry>
        <mesh filename="package://alfie_urdf/meshes/shoulder_bearing.obj" scale="1. 1. 1."/>
      </geometry>
      <material name="plastic_white"/>
    </visual>
    <visual>
      <origin xyz="-0.0206912 -0.0000007 -0.0509092" rpy="0. 1.5707964 0. "/>
      <geometry>
        <mesh filename="package://alfie_urdf/meshes/st3215.obj" scale="1. 1. 1."/>
      </geometry>
      <material name="plastic_black"/>
    </visual>
    <visual>
      <origin xyz="0.0206675 0.0000265 -0.0508856" rpy="3.1415927 1.5707964 0. "/>
      <geometry>
        <mesh filename="package://alfie_urdf/meshes/st3215.obj" scale="1. 1. 1."/>
      </geometry>
      <material name="plastic_black"/>
    </visual>
    <visual>
      <origin xyz="-0.0206912 -0.0000007 -0.0509092" rpy="0. 1.5707964 0. "/>
      <geometry>
        <mesh filename="package://alfie_urdf/meshes/active_horn.obj" scale="1. 1. 1."/>
      </geometry>
      <material name="plastic_white"/>
    </visual>
  </link>

  <link name="left_wrist_link">
    <inertial>
      <origin xyz="0. -0.0528719 0.019 " rpy="0. 0. 0."/>
      <mass value="0.0014148"/>
      <inertia ixx="0." ixy="-0." ixz="-0." iyy="0.0000001" iyz="-0." izz="0."/>
    </inertial>
    <visual>
      <origin xyz="0.0000108 -0.020328 0.0188602" rpy="-1.5707965 0. -1.5707964"/>
      <geometry>
        <mesh filename="package://alfie_urdf/meshes/wrist.obj" scale="1. 1. 1."/>
      </geometry>
      <material name="body_black"/>
    </visual>
    <visual>
      <origin xyz="0. -0.038 0.019" rpy="1.5707964 1.5707961 -3.1415927"/>
      <geometry>
        <mesh filename="package://alfie_urdf/meshes/st3215.obj" scale="1. 1. 1."/>
      </geometry>
      <material name="plastic_black"/>
    </visual>
    <visual>
      <origin xyz="0. -0.038 0.019" rpy="1.5707964 -0.0000002 -3.1415927"/>
      <geometry>
        <mesh filename="package://alfie_urdf/meshes/active_horn.obj" scale="1. 1. 1."/>
      </geometry>
      <material name="plastic_white"/>
    </visual>
  </link>

  <link name="mecanum_fl_link">
    <inertial>
      <origin xyz="0.030705 -0.0004024 0.0282788" rpy="0. 0. 0."/>
      <mass value="0.0152798"/>
      <inertia ixx="0.0000015" ixy="0." ixz="-0." iyy="0.0000004" iyz="0." izz="0.0000015"/>
    </inertial>
    <visual>
      <origin xyz="0.0237753 0.0193919 0.0281856" rpy="3.1415927 0. -0.8726646"/>
      <geometry>
        <mesh filename="package://alfie_urdf/meshes/roller.obj" scale="1. 1. 1."/>
      </geometry>
      <material name="rubber_black"/>
    </visual>
    <visual>
      <origin xyz="-0.014912 0.02679 0.0282389" rpy="2.186276 0.5235988 1.4789153"/>
      <geometry>
        <mesh filename="package://alfie_urdf/meshes/roller.obj" scale="1. 1. 1."/>
      </geometry>
      <material name="rubber_black"/>
    </visual>
    <visual>
      <origin xyz="0.0001322 -0.0000806 -0.018527 " rpy="-1.5707964 -1.5707964 0. "/>
      <geometry>
        <mesh filename="package://alfie_urdf/meshes/mecanum_fl_link_hub.obj" scale="1. 1. 1."/>
      </geometry>
      <material name="aluminum_black"/>
    </visual>
    <visual>
      <origin xyz="-0.0290498 -0.0101026 0.0282005" rpy="-2.186276 0.5235988 0.9645456"/>
      <geometry>
        <mesh filename="package://alfie_urdf/meshes/roller.obj" scale="1. 1. 1."/>
      </geometry>
      <material name="rubber_black"/>
    </visual>
    <visual>
      <origin xyz="-0.0157596 -0.0264119 0.0282005" rpy="-2.186276 0.5235988 1.6626773"/>
      <geometry>
        <mesh filename="package://alfie_urdf/meshes/roller.obj" scale="1. 1. 1."/>
      </geometry>
      <material name="rubber_black"/>
    </visual>
    <visual>
      <origin xyz="0.0232258 -0.0200468 0.0281856" rpy="-3.1415927 0. -2.268928 "/>
      <geometry>
        <mesh filename="package://alfie_urdf/meshes/roller.obj" scale="1. 1. 1."/>
      </geometry>
      <material name="rubber_black"/>
    </visual>
    <visual>
      <origin xyz="0.005797 0.0301076 0.0282389" rpy="2.186276 0.5235988 0.7807837"/>
      <geometry>
        <mesh filename="package://alfie_urdf/meshes/roller.obj" scale="1. 1. 1."/>
      </geometry>
      <material name="rubber_black"/>
    </visual>
    <visual>
      <origin xyz="-0.0286436 0.010937 0.0282389" rpy="2.186276 0.5235988 2.177047 "/>
      <geometry>
        <mesh filename="package://alfie_urdf/meshes/roller.obj" scale="1. 1. 1."/>
      </geometry>
      <material name="rubber_black"/>
    </visual>
    <visual>
      <origin xyz="0.0049047 -0.0303628 0.0282005" rpy="-2.186276 0.5235988 2.360809 "/>
      <geometry>
        <mesh filename="package://alfie_urdf/meshes/roller.obj" scale="1. 1. 1."/>
      </geometry>
      <material name="rubber_black"/>
    </visual>
    <visual>
      <origin xyz="0.0306778 -0.0004275 0.0281856" rpy="3.1415927 0. -1.5707964"/>
      <geometry>
        <mesh filename="package://alfie_urdf/meshes/roller.obj" scale="1. 1. 1."/>
      </geometry>
      <material name="rubber_black"/>
    </visual>
    <collision>
      <origin xyz="0.0237753 0.0193919 0.0281856" rpy="3.1415927 0. -0.8726646"/>
      <geometry>
        <mesh filename="package://alfie_urdf/meshes/roller.obj" scale="1. 1. 1."/>
      </geometry>
    </collision>
    <collision>
      <origin xyz="-0.014912 0.02679 0.0282389" rpy="2.186276 0.5235988 1.4789153"/>
      <geometry>
        <mesh filename="package://alfie_urdf/meshes/roller.obj" scale="1. 1. 1."/>
      </geometry>
    </collision>
    <collision>
      <origin xyz="-0.0290498 -0.0101026 0.0282005" rpy="-2.186276 0.5235988 0.9645456"/>
      <geometry>
        <mesh filename="package://alfie_urdf/meshes/roller.obj" scale="1. 1. 1."/>
      </geometry>
    </collision>
    <collision>
      <origin xyz="-0.0157596 -0.0264119 0.0282005" rpy="-2.186276 0.5235988 1.6626773"/>
      <geometry>
        <mesh filename="package://alfie_urdf/meshes/roller.obj" scale="1. 1. 1."/>
      </geometry>
    </collision>
    <collision>
      <origin xyz="0.0232258 -0.0200468 0.0281856" rpy="-3.1415927 0. -2.268928 "/>
      <geometry>
        <mesh filename="package://alfie_urdf/meshes/roller.obj" scale="1. 1. 1."/>
      </geometry>
    </collision>
    <collision>
      <origin xyz="0.005797 0.0301076 0.0282389" rpy="2.186276 0.5235988 0.7807837"/>
      <geometry>
        <mesh filename="package://alfie_urdf/meshes/roller.obj" scale="1. 1. 1."/>
      </geometry>
    </collision>
    <collision>
      <origin xyz="-0.0286436 0.010937 0.0282389" rpy="2.186276 0.5235988 2.177047 "/>
      <geometry>
        <mesh filename="package://alfie_urdf/meshes/roller.obj" scale="1. 1. 1."/>
      </geometry>
    </collision>
    <collision>
      <origin xyz="0.0049047 -0.0303628 0.0282005" rpy="-2.186276 0.5235988 2.360809 "/>
      <geometry>
        <mesh filename="package://alfie_urdf/meshes/roller.obj" scale="1. 1. 1."/>
      </geometry>
    </collision>
    <collision>
      <origin xyz="0.0306778 -0.0004275 0.0281856" rpy="3.1415927 0. -1.5707964"/>
      <geometry>
        <mesh filename="package://alfie_urdf/meshes/roller.obj" scale="1. 1. 1."/>
      </geometry>
    </collision>
  </link>

  <link name="mecanum_fr_link">
    <inertial>
      <origin xyz="0. -0. -0.0279484" rpy="0. 0. 0."/>
      <mass value="0.2098582"/>
      <inertia ixx="0.0000781" ixy="0." ixz="0." iyy="0.0000822" iyz="-0." izz="0.0000781"/>
    </inertial>
    <visual>
      <origin xyz="0.0290288 -0.0101091 -0.0282764" rpy="3.0898395 0.0013398 1.2734836"/>
      <geometry>
        <mesh filename="package://alfie_urdf/meshes/roller.obj" scale="1. 1. 1."/>
      </geometry>
      <material name="rubber_black"/>
    </visual>
    <visual>
      <origin xyz="-0.0231955 -0.0200459 -0.0282591" rpy="-2.133727 0.5903624 -1.8805304"/>
      <geometry>
        <mesh filename="package://alfie_urdf/meshes/roller.obj" scale="1. 1. 1."/>
      </geometry>
      <material name="rubber_black"/>
    </visual>
    <visual>
      <origin xyz="-0.0057898 0.0302133 -0.02825 " rpy="2.543315 0.189642 -2.368782"/>
      <geometry>
        <mesh filename="package://alfie_urdf/meshes/roller.obj" scale="1. 1. 1."/>
      </geometry>
      <material name="rubber_black"/>
    </visual>
    <visual>
      <origin xyz="0.0287354 0.0109153 -0.0282764" rpy="3.0898395 0.0013398 1.9716153"/>
      <geometry>
        <mesh filename="package://alfie_urdf/meshes/roller.obj" scale="1. 1. 1."/>
      </geometry>
      <material name="rubber_black"/>
    </visual>
    <visual>
      <origin xyz="0.0149965 0.0268394 -0.028273 " rpy="2.9902365 0.0114981 2.76935 "/>
      <geometry>
        <mesh filename="package://alfie_urdf/meshes/roller.obj" scale="1. 1. 1."/>
      </geometry>
      <material name="rubber_black"/>
    </visual>
    <visual>
      <origin xyz="-0.0307403 -0.0004917 -0.0282137" rpy="2.0234883 0.7461636 -0.4526919"/>
      <geometry>
        <mesh filename="package://alfie_urdf/meshes/roller.obj" scale="1. 1. 1."/>
      </geometry>
      <material name="rubber_black"/>
    </visual>
    <visual>
      <origin xyz="0.0157454 -0.026407 -0.028273 " rpy="2.9902365 0.0114981 0.6749548"/>
      <geometry>
        <mesh filename="package://alfie_urdf/meshes/roller.obj" scale="1. 1. 1."/>
      </geometry>
      <material name="rubber_black"/>
    </visual>
    <visual>
      <origin xyz="-0.0238669 0.0194043 -0.0282286" rpy="2.240851 0.4593191 -1.3681865"/>
      <geometry>
        <mesh filename="package://alfie_urdf/meshes/roller.obj" scale="1. 1. 1."/>
      </geometry>
      <material name="rubber_black"/>
    </visual>
    <visual>
      <origin xyz="-0.0048618 -0.0302659 -0.0282377" rpy="-1.8992568 0.9467018 -1.4168686"/>
      <geometry>
        <mesh filename="package://alfie_urdf/meshes/roller.obj" scale="1. 1. 1."/>
      </geometry>
      <material name="rubber_black"/>
    </visual>
    <visual>
      <origin xyz="-0.0001322 0.0000806 0.018527 " rpy="1.5707964 -1.5707964 0. "/>
      <geometry>
        <mesh filename="package://alfie_urdf/meshes/mecanum_fr_link_hub.obj" scale="1. 1. 1."/>
      </geometry>
      <material name="aluminum_black"/>
    </visual>
    <collision>
      <origin xyz="0.0290288 -0.0101091 -0.0282764" rpy="3.0898395 0.0013398 1.2734836"/>
      <geometry>
        <mesh filename="package://alfie_urdf/meshes/roller.obj" scale="1. 1. 1."/>
      </geometry>
    </collision>
    <collision>
      <origin xyz="-0.0231955 -0.0200459 -0.0282591" rpy="-2.133727 0.5903624 -1.8805304"/>
      <geometry>
        <mesh filename="package://alfie_urdf/meshes/roller.obj" scale="1. 1. 1."/>
      </geometry>
    </collision>
    <collision>
      <origin xyz="-0.0057898 0.0302133 -0.02825 " rpy="2.543315 0.189642 -2.368782"/>
      <geometry>
        <mesh filename="package://alfie_urdf/meshes/roller.obj" scale="1. 1. 1."/>
      </geometry>
    </collision>
    <collision>
      <origin xyz="0.0287354 0.0109153 -0.0282764" rpy="3.0898395 0.0013398 1.9716153"/>
      <geometry>
        <mesh filename="package://alfie_urdf/meshes/roller.obj" scale="1. 1. 1."/>
      </geometry>
    </collision>
    <collision>
      <origin xyz="0.0149965 0.0268394 -0.028273 " rpy="2.9902365 0.0114981 2.76935 "/>
      <geometry>
        <mesh filename="package://alfie_urdf/meshes/roller.obj" scale="1. 1. 1."/>
      </geometry>
    </collision>
    <collision>
      <origin xyz="-0.0307403 -0.0004917 -0.0282137" rpy="2.0234883 0.7461636 -0.4526919"/>
      <geometry>
        <mesh filename="package://alfie_urdf/meshes/roller.obj" scale="1. 1. 1."/>
      </geometry>
    </collision>
    <collision>
      <origin xyz="0.0157454 -0.026407 -0.028273 " rpy="2.9902365 0.0114981 0.6749548"/>
      <geometry>
        <mesh filename="package://alfie_urdf/meshes/roller.obj" scale="1. 1. 1."/>
      </geometry>
    </collision>
    <collision>
      <origin xyz="-0.0238669 0.0194043 -0.0282286" rpy="2.240851 0.4593191 -1.3681865"/>
      <geometry>
        <mesh filename="package://alfie_urdf/meshes/roller.obj" scale="1. 1. 1."/>
      </geometry>
    </collision>
    <collision>
      <origin xyz="-0.0048618 -0.0302659 -0.0282377" rpy="-1.8992568 0.9467018 -1.4168686"/>
      <geometry>
        <mesh filename="package://alfie_urdf/meshes/roller.obj" scale="1. 1. 1."/>
      </geometry>
    </collision>
  </link>

  <link name="mecanum_rl_link">
    <inertial>
      <origin xyz="0.0237801 0.0194285 0.0281847" rpy="0. 0. 0."/>
      <mass value="0.0152798"/>
      <inertia ixx="0.0000007" ixy="-0.0000001" ixz="-0.0000005" iyy="0.0000015" iyz="-0." izz="0.0000012"/>
    </inertial>
    <visual>
      <origin xyz="-0.0289972 -0.0100267 0.0282098" rpy="-1.2217305 -1.5707964 0. "/>
      <geometry>
        <mesh filename="package://alfie_urdf/meshes/roller.obj" scale="1. 1. 1."/>
      </geometry>
      <material name="rubber_black"/>
    </visual>
    <visual>
      <origin xyz="0.0232493 -0.0201361 0.0282246" rpy="-0.9553166 -0.5235988 3.0589406"/>
      <geometry>
        <mesh filename="package://alfie_urdf/meshes/roller.obj" scale="1. 1. 1."/>
      </geometry>
      <material name="rubber_black"/>
    </visual>
    <visual>
      <origin xyz="0.0057591 0.0301143 0.0282631" rpy="0.9553166 -0.5235988 0.7807837"/>
      <geometry>
        <mesh filename="package://alfie_urdf/meshes/roller.obj" scale="1. 1. 1."/>
      </geometry>
      <material name="rubber_black"/>
    </visual>
    <visual>
      <origin xyz="-0.0286582 0.0109581 0.0282098" rpy="-1.9198622 -1.5707964 0. "/>
      <geometry>
        <mesh filename="package://alfie_urdf/meshes/roller.obj" scale="1. 1. 1."/>
      </geometry>
      <material name="rubber_black"/>
    </visual>
    <visual>
      <origin xyz="-0.0149097 0.0268156 0.0282098" rpy="-2.6179938 -1.5707964 0. "/>
      <geometry>
        <mesh filename="package://alfie_urdf/meshes/roller.obj" scale="1. 1. 1."/>
      </geometry>
      <material name="rubber_black"/>
    </visual>
    <visual>
      <origin xyz="0.0306724 -0.0004299 0.0282755" rpy="0.7382554 -0.2971161 -0.8325408"/>
      <geometry>
        <mesh filename="package://alfie_urdf/meshes/roller.obj" scale="1. 1. 1."/>
      </geometry>
      <material name="rubber_black"/>
    </visual>
    <visual>
      <origin xyz="-0.0157681 -0.0263199 0.0282098" rpy="-0.5235988 -1.5707964 0. "/>
      <geometry>
        <mesh filename="package://alfie_urdf/meshes/roller.obj" scale="1. 1. 1."/>
      </geometry>
      <material name="rubber_black"/>
    </visual>
    <visual>
      <origin xyz="0.0001322 0.0000806 -0.018527 " rpy="1.5707964 1.5707964 0. "/>
      <geometry>
        <mesh filename="package://alfie_urdf/meshes/mecanum_rl_link_hub.obj" scale="1. 1. 1."/>
      </geometry>
      <material name="aluminum_black"/>
    </visual>
    <visual>
      <origin xyz="0.0048668 -0.0303695 0.0282246" rpy="-0.9553166 -0.5235988 2.360809 "/>
      <geometry>
        <mesh filename="package://alfie_urdf/meshes/roller.obj" scale="1. 1. 1."/>
      </geometry>
      <material name="rubber_black"/>
    </visual>
    <visual>
      <origin xyz="0.0237688 0.019367 0.0282631" rpy="0.9553166 -0.5235988 0.082652 "/>
      <geometry>
        <mesh filename="package://alfie_urdf/meshes/roller.obj" scale="1. 1. 1."/>
      </geometry>
      <material name="rubber_black"/>
    </visual>
    <collision>
      <origin xyz="-0.0289972 -0.0100267 0.0282098" rpy="-1.2217305 -1.5707964 0. "/>
      <geometry>
        <mesh filename="package://alfie_urdf/meshes/roller.obj" scale="1. 1. 1."/>
      </geometry>
    </collision>
    <collision>
      <origin xyz="0.0232493 -0.0201361 0.0282246" rpy="-0.9553166 -0.5235988 3.0589406"/>
      <geometry>
        <mesh filename="package://alfie_urdf/meshes/roller.obj" scale="1. 1. 1."/>
      </geometry>
    </collision>
    <collision>
      <origin xyz="0.0057591 0.0301143 0.0282631" rpy="0.9553166 -0.5235988 0.7807837"/>
      <geometry>
        <mesh filename="package://alfie_urdf/meshes/roller.obj" scale="1. 1. 1."/>
      </geometry>
    </collision>
    <collision>
      <origin xyz="-0.0286582 0.0109581 0.0282098" rpy="-1.9198622 -1.5707964 0. "/>
      <geometry>
        <mesh filename="package://alfie_urdf/meshes/roller.obj" scale="1. 1. 1."/>
      </geometry>
    </collision>
    <collision>
      <origin xyz="-0.0149097 0.0268156 0.0282098" rpy="-2.6179938 -1.5707964 0. "/>
      <geometry>
        <mesh filename="package://alfie_urdf/meshes/roller.obj" scale="1. 1. 1."/>
      </geometry>
    </collision>
    <collision>
      <origin xyz="0.0306724 -0.0004299 0.0282755" rpy="0.7382554 -0.2971161 -0.8325408"/>
      <geometry>
        <mesh filename="package://alfie_urdf/meshes/roller.obj" scale="1. 1. 1."/>
      </geometry>
    </collision>
    <collision>
      <origin xyz="-0.0157681 -0.0263199 0.0282098" rpy="-0.5235988 -1.5707964 0. "/>
      <geometry>
        <mesh filename="package://alfie_urdf/meshes/roller.obj" scale="1. 1. 1."/>
      </geometry>
    </collision>
    <collision>
      <origin xyz="0.0048668 -0.0303695 0.0282246" rpy="-0.9553166 -0.5235988 2.360809 "/>
      <geometry>
        <mesh filename="package://alfie_urdf/meshes/roller.obj" scale="1. 1. 1."/>
      </geometry>
    </collision>
    <collision>
      <origin xyz="0.0237688 0.019367 0.0282631" rpy="0.9553166 -0.5235988 0.082652 "/>
      <geometry>
        <mesh filename="package://alfie_urdf/meshes/roller.obj" scale="1. 1. 1."/>
      </geometry>
    </collision>
  </link>

  <link name="mecanum_rr_link">
    <inertial>
      <origin xyz="0.030705 0.0004024 -0.0282788" rpy="0. 0. 0."/>
      <mass value="0.0152798"/>
      <inertia ixx="0.0000015" ixy="-0." ixz="-0." iyy="0.0000004" iyz="-0." izz="0.0000015"/>
    </inertial>
    <visual>
      <origin xyz="0.0238566 -0.0193678 -0.0282563" rpy="-1.5170586 -1.4634758 -0.644394 "/>
      <geometry>
        <mesh filename="package://alfie_urdf/meshes/roller.obj" scale="1. 1. 1."/>
      </geometry>
      <material name="rubber_black"/>
    </visual>
    <visual>
      <origin xyz="-0.014992 -0.0268577 -0.0282036" rpy="0.9966134 -0.5756602 0.4730145"/>
      <geometry>
        <mesh filename="package://alfie_urdf/meshes/roller.obj" scale="1. 1. 1."/>
      </geometry>
      <material name="rubber_black"/>
    </visual>
    <visual>
      <origin xyz="0.0001322 0.0000806 0.018527 " rpy="1.5707964 1.5707964 0. "/>
      <geometry>
        <mesh filename="package://alfie_urdf/meshes/mecanum_rr_link_hub.obj" scale="1. 1. 1."/>
      </geometry>
      <material name="aluminum_black"/>
    </visual>
    <visual>
      <origin xyz="-0.0289869 0.0100279 -0.0282491" rpy="-1.1055627 -0.7273656 -3.025425 "/>
      <geometry>
        <mesh filename="package://alfie_urdf/meshes/roller.obj" scale="1. 1. 1."/>
      </geometry>
      <material name="rubber_black"/>
    </visual>
    <visual>
      <origin xyz="-0.0157486 0.02631 -0.0282419" rpy="-0.9966134 -0.5756602 2.6685781"/>
      <geometry>
        <mesh filename="package://alfie_urdf/meshes/roller.obj" scale="1. 1. 1."/>
      </geometry>
      <material name="rubber_black"/>
    </visual>
    <visual>
      <origin xyz="0.0232311 0.0201359 -0.0282505" rpy="1.5170586 -1.4634758 -2.4971986"/>
      <geometry>
        <mesh filename="package://alfie_urdf/meshes/roller.obj" scale="1. 1. 1."/>
      </geometry>
      <material name="rubber_black"/>
    </visual>
    <visual>
      <origin xyz="0.0057783 -0.0302104 -0.0282027" rpy="0.9853742 -0.5611966 1.159907 "/>
      <geometry>
        <mesh filename="package://alfie_urdf/meshes/roller.obj" scale="1. 1. 1."/>
      </geometry>
      <material name="rubber_black"/>
    </visual>
    <visual>
      <origin xyz="-0.028749 -0.0109475 -0.0282128" rpy="1.1055627 -0.7273656 -0.1161676"/>
      <geometry>
        <mesh filename="package://alfie_urdf/meshes/roller.obj" scale="1. 1. 1."/>
      </geometry>
      <material name="rubber_black"/>
    </visual>
    <visual>
      <origin xyz="0.0048482 0.0302768 -0.0282411" rpy="-0.9853742 -0.5611966 1.9816856"/>
      <geometry>
        <mesh filename="package://alfie_urdf/meshes/roller.obj" scale="1. 1. 1."/>
      </geometry>
      <material name="rubber_black"/>
    </visual>
    <visual>
      <origin xyz="0.0306778 0.0004275 -0.0281856" rpy="0. 0. 1.5707964"/>
      <geometry>
        <mesh filename="package://alfie_urdf/meshes/roller.obj" scale="1. 1. 1."/>
      </geometry>
      <material name="rubber_black"/>
    </visual>
    <collision>
      <origin xyz="0.0238566 -0.0193678 -0.0282563" rpy="-1.5170586 -1.4634758 -0.644394 "/>
      <geometry>
        <mesh filename="package://alfie_urdf/meshes/roller.obj" scale="1. 1. 1."/>
      </geometry>
    </collision>
    <collision>
      <origin xyz="-0.014992 -0.0268577 -0.0282036" rpy="0.9966134 -0.5756602 0.4730145"/>
      <geometry>
        <mesh filename="package://alfie_urdf/meshes/roller.obj" scale="1. 1. 1."/>
      </geometry>
    </collision>
    <collision>
      <origin xyz="-0.0289869 0.0100279 -0.0282491" rpy="-1.1055627 -0.7273656 -3.025425 "/>
      <geometry>
        <mesh filename="package://alfie_urdf/meshes/roller.obj" scale="1. 1. 1."/>
      </geometry>
    </collision>
    <collision>
      <origin xyz="-0.0157486 0.02631 -0.0282419" rpy="-0.9966134 -0.5756602 2.6685781"/>
      <geometry>
        <mesh filename="package://alfie_urdf/meshes/roller.obj" scale="1. 1. 1."/>
      </geometry>
    </collision>
    <collision>
      <origin xyz="0.0232311 0.0201359 -0.0282505" rpy="1.5170586 -1.4634758 -2.4971986"/>
      <geometry>
        <mesh filename="package://alfie_urdf/meshes/roller.obj" scale="1. 1. 1."/>
      </geometry>
    </collision>
    <collision>
      <origin xyz="0.0057783 -0.0302104 -0.0282027" rpy="0.9853742 -0.5611966 1.159907 "/>
      <geometry>
        <mesh filename="package://alfie_urdf/meshes/roller.obj" scale="1. 1. 1."/>
      </geometry>
    </collision>
    <collision>
      <origin xyz="-0.028749 -0.0109475 -0.0282128" rpy="1.1055627 -0.7273656 -0.1161676"/>
      <geometry>
        <mesh filename="package://alfie_urdf/meshes/roller.obj" scale="1. 1. 1."/>
      </geometry>
    </collision>
    <collision>
      <origin xyz="0.0048482 0.0302768 -0.0282411" rpy="-0.9853742 -0.5611966 1.9816856"/>
      <geometry>
        <mesh filename="package://alfie_urdf/meshes/roller.obj" scale="1. 1. 1."/>
      </geometry>
    </collision>
    <collision>
      <origin xyz="0.0306778 0.0004275 -0.0281856" rpy="0. 0. 1.5707964"/>
      <geometry>
        <mesh filename="package://alfie_urdf/meshes/roller.obj" scale="1. 1. 1."/>
      </geometry>
    </collision>
  </link>

  <link name="neck2_link">
    <inertial>
      <origin xyz="-0. 0. 0.0264545" rpy="0. 0. 0."/>
      <mass value="0.0339002"/>
      <inertia ixx="0.0000129" ixy="0." ixz="0." iyy="0.0000141" iyz="0." izz="0.0000245"/>
    </inertial>
    <visual>
      <origin xyz="0. 0.015 -0.044" rpy="0. 0. 0."/>
      <geometry>
        <mesh filename="package://alfie_urdf/meshes/neck2_frame.obj" scale="1. 1. 1."/>
      </geometry>
      <material name="body_black"/>
    </visual>
  </link>

  <link name="neck3_link">
    <inertial>
      <origin xyz="0.0133899 0. 0.0195466" rpy="0. 0. 0."/>
      <mass value="0.0951702"/>
      <inertia ixx="0.0000129" ixy="0." ixz="-0." iyy="0.0000204" iyz="-0." izz="0.0000236"/>
    </inertial>
    <visual>
      <origin xyz="0. 0. 0.0215" rpy="3.1415927 0. 1.5707964"/>
      <geometry>
        <mesh filename="package://alfie_urdf/meshes/active_horn.obj" scale="1. 1. 1."/>
      </geometry>
      <material name="plastic_white"/>
    </visual>
    <visual>
      <origin xyz="0. 0. 0.02" rpy="3.1415927 0. 1.5707964"/>
      <geometry>
        <mesh filename="package://alfie_urdf/meshes/passive_horn.obj" scale="1. 1. 1."/>
      </geometry>
      <material name="plastic_white"/>
    </visual>
    <visual>
      <origin xyz="0.0346271 0.0001068 0.0194332" rpy="3.1415927 0. 1.5707964"/>
      <geometry>
        <mesh filename="package://alfie_urdf/meshes/neck3_frame.obj" scale="1. 1. 1."/>
      </geometry>
      <material name="body_black"/>
    </visual>
    <visual>
      <origin xyz="0. 0. 0.0215" rpy="3.1415927 0. 3.1415927"/>
      <geometry>
        <mesh filename="package://alfie_urdf/meshes/st3215.obj" scale="1. 1. 1."/>
      </geometry>
      <material name="plastic_black"/>
    </visual>
  </link>

  <link name="right_arm_lower_link">
    <inertial>
      <origin xyz="-0.0133899 -0. 0.0192034" rpy="0. 0. 0."/>
      <mass value="0.0951702"/>
      <inertia ixx="0.0000129" ixy="-0." ixz="0." iyy="0.0000204" iyz="-0." izz="0.0000236"/>
    </inertial>
    <visual>
      <origin xyz="0.0672499 0.5326688 -0.0786977" rpy="1.5707961 1.5707963 0. "/>
      <geometry>
        <mesh filename="package://alfie_urdf/meshes/tube.obj" scale="1. 1. 1."/>
      </geometry>
      <material name="plastic_black"/>
    </visual>
    <visual>
      <origin xyz="-0.2158563 -0.0012424 0.017225 " rpy="0.0000001 -0.0000001 1.5707965"/>
      <geometry>
        <mesh filename="package://alfie_urdf/meshes/passive_horn.obj" scale="1. 1. 1."/>
      </geometry>
      <material name="plastic_white"/>
    </visual>
    <visual>
      <origin xyz="0.06725 -0.539283 0.1163363" rpy="-1.5707963 -1.5707963 0. "/>
      <geometry>
        <mesh filename="package://alfie_urdf/meshes/wrist_frame.obj" scale="1. 1. 1."/>
      </geometry>
      <material name="aluminum_black"/>
    </visual>
    <visual>
      <origin xyz="0.06725 -0.5392672 0.1163611" rpy="-1.5707963 -1.5707963 0. "/>
      <geometry>
        <mesh filename="package://alfie_urdf/meshes/bracket_lower.obj" scale="1. 1. 1."/>
      </geometry>
      <material name="plastic_grey"/>
    </visual>
    <visual>
      <origin xyz="0.06725 -0.5392672 0.1163611" rpy="-1.5707963 -1.5707963 0. "/>
      <geometry>
        <mesh filename="package://alfie_urdf/meshes/elbow_frame.obj" scale="1. 1. 1."/>
      </geometry>
      <material name="aluminum_black"/>
    </visual>
    <visual>
      <origin xyz="0. -0. 0.01725" rpy="-0.0000001 0.0000001 -1.5707963"/>
      <geometry>
        <mesh filename="package://alfie_urdf/meshes/passive_horn.obj" scale="1. 1. 1."/>
      </geometry>
      <material name="plastic_white"/>
    </visual>
    <visual>
      <origin xyz="0.06725 -0.5392672 0.1163611" rpy="-1.5707963 -1.5707963 0. "/>
      <geometry>
        <mesh filename="package://alfie_urdf/meshes/bracket_upper.obj" scale="1. 1. 1."/>
      </geometry>
      <material name="plastic_grey"/>
    </visual>
    <visual>
      <origin xyz="0.06725 -0.539283 0.1163363" rpy="-1.5707963 -1.5707963 0. "/>
      <geometry>
        <mesh filename="package://alfie_urdf/meshes/bracket_lower.obj" scale="1. 1. 1."/>
      </geometry>
      <material name="plastic_grey"/>
    </visual>
    <visual>
      <origin xyz="-0.2158563 -0.005356 0.0204384" rpy="3.1415925 -0.0000001 -3.1415925"/>
      <geometry>
        <mesh filename="package://alfie_urdf/meshes/st3215.obj" scale="1. 1. 1."/>
      </geometry>
      <material name="plastic_black"/>
    </visual>
    <visual>
      <origin xyz="-0.2158563 -0.0012424 0.017225 " rpy="0.0000001 -0.0000001 1.5707965"/>
      <geometry>
        <mesh filename="package://alfie_urdf/meshes/active_horn.obj" scale="1. 1. 1."/>
      </geometry>
      <material name="plastic_white"/>
    </visual>
    <visual>
      <origin xyz="0. -0. 0.01725" rpy="-0.0000001 0.0000001 -1.5707963"/>
      <geometry>
        <mesh filename="package://alfie_urdf/meshes/active_horn.obj" scale="1. 1. 1."/>
      </geometry>
      <material name="plastic_white"/>
    </visual>
    <visual>
      <origin xyz="0.06725 -0.539283 0.1163363" rpy="-1.5707963 -1.5707963 0. "/>
      <geometry>
        <mesh filename="package://alfie_urdf/meshes/bracket_upper.obj" scale="1. 1. 1."/>
      </geometry>
      <material name="plastic_grey"/>
    </visual>
    <visual>
      <origin xyz="0. -0. 0.01725" rpy="0.0000001 0.0000001 0.0000001"/>
      <geometry>
        <mesh filename="package://alfie_urdf/meshes/st3215.obj" scale="1. 1. 1."/>
      </geometry>
      <material name="plastic_black"/>
    </visual>
  </link>

  <link name="right_arm_upper_link">
    <inertial>
      <origin xyz="0.1212154 -0.0000903 0.03801 " rpy="0. 0. 0."/>
      <mass value="0.1877193"/>
      <inertia ixx="0.0009182" ixy="-0." ixz="-0." iyy="0.0008838" iyz="-0." izz="0.0000578"/>
    </inertial>
    <visual>
      <origin xyz="0.7760408 0.0370184 0.1359393" rpy="-0. -1.5707961 0. "/>
      <geometry>
        <mesh filename="package://alfie_urdf/meshes/upper_frame.obj" scale="1. 1. 1."/>
      </geometry>
      <material name="aluminum_black"/>
    </visual>
  </link>

  <link name="right_gripper_active_link">
    <inertial>
      <origin xyz="-0.0001356 -0.0333035 0.005 " rpy="0. 0. 0."/>
      <mass value="0.0211625"/>
      <inertia ixx="0.0000013" ixy="-0." ixz="-0." iyy="0.0000198" iyz="0." izz="0.0000203"/>
    </inertial>
    <visual>
      <origin xyz="-0.03125 0. 0.015 " rpy="-3.1415927 0. -3.1415927"/>
      <geometry>
        <mesh filename="package://alfie_urdf/meshes/gripper_liner.obj" scale="1. 1. 1."/>
      </geometry>
      <material name="rubber_orange"/>
    </visual>
    <visual>
      <origin xyz="-0.03125 0. 0.015 " rpy="-3.1415927 0. -3.1415927"/>
      <geometry>
        <mesh filename="package://alfie_urdf/meshes/gripper.obj" scale="1. 1. 1."/>
      </geometry>
      <material name="body_black"/>
    </visual>
    <collision>
      <origin xyz="-0.0313332 -0.0001633 -0.0049882" rpy="0. 0. 0."/>
      <geometry>
        <mesh filename="package://alfie_urdf/meshes/gripper_active_collision.obj" scale="1. 1. 1."/>
      </geometry>
      <material name="plastic_black"/>
    </collision>
  </link>

  <link name="right_gripper_passive_link">
    <inertial>
      <origin xyz="0.006577 -0.0528765 0.0049983" rpy="0. 0. 0."/>
      <mass value="0.0070743"/>
      <inertia ixx="0.0000002" ixy="0." ixz="0." iyy="0.0000039" iyz="0." izz="0.000004"/>
    </inertial>
    <visual>
      <origin xyz="0.03125 -0. -0.005 " rpy="0. 0. 0."/>
      <geometry>
        <mesh filename="package://alfie_urdf/meshes/gripper.obj" scale="1. 1. 1."/>
      </geometry>
      <material name="body_black"/>
    </visual>
    <visual>
      <origin xyz="0.03125 -0. -0.005 " rpy="0. 0. 0."/>
      <geometry>
        <mesh filename="package://alfie_urdf/meshes/gripper_liner.obj" scale="1. 1. 1."/>
      </geometry>
      <material name="rubber_orange"/>
    </visual>
    <collision>
      <origin xyz="0.031 -0.0003 -0.0044" rpy="0. 0. 0."/>
      <geometry>
        <mesh filename="package://alfie_urdf/meshes/gripper_passive_collision.obj" scale="1. 1. 1."/>
      </geometry>
    </collision>
  </link>

  <link name="right_hand_link">
    <inertial>
      <origin xyz="-0.0009873 -0.0011172 0.0124377" rpy="0. 0. 0."/>
      <mass value="0.0225604"/>
      <inertia ixx="0.0000078" ixy="0." ixz="-0." iyy="0.0000033" iyz="0." izz="0.0000065"/>
    </inertial>
    <visual>
      <origin xyz="0.02245 0.015625 0.021 " rpy="1.5707964 -0.0148905 1.5707964"/>
      <geometry>
        <mesh filename="package://alfie_urdf/meshes/st3215.obj" scale="1. 1. 1."/>
      </geometry>
      <material name="plastic_black"/>
    </visual>
    <visual>
      <origin xyz="0.01 0.015625 0.021 " rpy="-1.5707964 0. 1.5707964"/>
      <geometry>
        <mesh filename="package://alfie_urdf/meshes/hand_frame.obj" scale="1. 1. 1."/>
      </geometry>
      <material name="aluminum_black"/>
    </visual>
  </link>

  <link name="right_shoulder_link">
    <inertial>
      <origin xyz="-0.035563 -0.0000007 -0.0509092" rpy="0. 0. 0."/>
      <mass value="0.0014148"/>
      <inertia ixx="0.0000001" ixy="0." ixz="-0." iyy="0." iyz="-0." izz="0."/>
    </inertial>
    <visual>
      <origin xyz="0. -0. 0." rpy="0. 0. 3.1415927"/>
      <geometry>
        <mesh filename="package://alfie_urdf/meshes/shoulder_frame.obj" scale="1. 1. 1."/>
      </geometry>
      <material name="aluminum_black"/>
    </visual>
    <visual>
      <origin xyz="0.0206675 0.0000265 -0.0508856" rpy="3.1415927 1.5707964 0. "/>
      <geometry>
        <mesh filename="package://alfie_urdf/meshes/active_horn.obj" scale="1. 1. 1."/>
      </geometry>
      <material name="plastic_white"/>
    </visual>
    <visual>
      <origin xyz="-0.0206912 -0.0000007 -0.0509092" rpy="0. 1.5707964 0. "/>
      <geometry>
        <mesh filename="package://alfie_urdf/meshes/passive_horn.obj" scale="1. 1. 1."/>
      </geometry>
      <material name="plastic_white"/>
    </visual>
    <visual>
      <origin xyz="0.0206675 0.0000265 -0.0508856" rpy="3.1415927 1.5707964 0. "/>
      <geometry>
        <mesh filename="package://alfie_urdf/meshes/passive_horn.obj" scale="1. 1. 1."/>
      </geometry>
      <material name="plastic_white"/>
    </visual>
    <visual>
      <origin xyz="0. -0. 0." rpy="0. 0. 3.1415927"/>
      <geometry>
        <mesh filename="package://alfie_urdf/meshes/shoulder_bearing.obj" scale="1. 1. 1."/>
      </geometry>
      <material name="plastic_white"/>
    </visual>
    <visual>
      <origin xyz="-0.0206912 -0.0000007 -0.0509092" rpy="0. 1.5707964 0. "/>
      <geometry>
        <mesh filename="package://alfie_urdf/meshes/st3215.obj" scale="1. 1. 1."/>
      </geometry>
      <material name="plastic_black"/>
    </visual>
    <visual>
      <origin xyz="0.0206675 0.0000265 -0.0508856" rpy="3.1415927 1.5707964 0. "/>
      <geometry>
        <mesh filename="package://alfie_urdf/meshes/st3215.obj" scale="1. 1. 1."/>
      </geometry>
      <material name="plastic_black"/>
    </visual>
    <visual>
      <origin xyz="-0.0206912 -0.0000007 -0.0509092" rpy="0. 1.5707964 0. "/>
      <geometry>
        <mesh filename="package://alfie_urdf/meshes/active_horn.obj" scale="1. 1. 1."/>
      </geometry>
      <material name="plastic_white"/>
    </visual>
  </link>

  <link name="right_wrist_link">
    <inertial>
      <origin xyz="-0. -0.0528718 0.0185 " rpy="0. 0. 0."/>
      <mass value="0.0014148"/>
      <inertia ixx="0." ixy="0." ixz="-0." iyy="0.0000001" iyz="0." izz="0."/>
    </inertial>
    <visual>
      <origin xyz="-0.0000108 -0.020328 0.0186398" rpy="1.5707961 0. -1.5707964"/>
      <geometry>
        <mesh filename="package://alfie_urdf/meshes/wrist.obj" scale="1. 1. 1."/>
      </geometry>
      <material name="body_black"/>
    </visual>
    <visual>
      <origin xyz="-0. -0.038 0.0185" rpy="-1.5707749 -1.5707961 -0.0000214"/>
      <geometry>
        <mesh filename="package://alfie_urdf/meshes/st3215.obj" scale="1. 1. 1."/>
      </geometry>
      <material name="plastic_black"/>
    </visual>
    <visual>
      <origin xyz="-0. -0.038 0.0185" rpy="-1.5707964 0.0000002 -0. "/>
      <geometry>
        <mesh filename="package://alfie_urdf/meshes/active_horn.obj" scale="1. 1. 1."/>
      </geometry>
      <material name="plastic_white"/>
    </visual>
  </link>

</robot>
